call(){}

// Just to enable second error
fn main() {}
1{}

